<?xml version="1.0"?>
<robot xmlns:xacro="http://www.ros.org/wiki/xacro" name="gripx">

<material name="blue">
    <color rgba="0 0 0.8 1"/>
  </material>
  <material name="black">
    <color rgba="0 0 0 1"/>
  </material>
  <material name="white">
    <color rgba="1 1 1 1"/>
  </material>


    <link name="base_link">
    <!-- <inertial>
      <origin xyz="0.00244324 0.00015573 0.08616742" rpy="0 0 0" />
      <mass value="1.14608471" />
      <inertia ixx="0.0" ixy="0" ixz="0.0" iyy="0.0" iyz="0" izz="0.0" />
    </inertial> -->
    <visual>
      <origin xyz="0 0 0" rpy="0 0 0" />
      <geometry>
        <mesh filename="package://gripx_description/meshes/meshes/base_link.STL" />
      </geometry>
      <material name="">
        <color rgba="0.803 0.824 0.820 1" />
      </material>
    </visual>
    <collision>
      <origin xyz="0 0 0" rpy="0 0 0" />
      <geometry>
        <mesh filename="package://gripx_description/meshes/meshes/base_link.STL" />
      </geometry>
    </collision>
  </link>


  <link name="shoulder_link">
    <inertial>
      <origin xyz="2.477E-05 0.02213531 0.09937686" rpy="0 0 0" />
      <mass value="0.95974404" />
      <inertia ixx="0.00165947" ixy="2E-08" ixz="3.6E-07" iyy="0.00140355" iyz="0.00034927" izz="0.00089493" />
    </inertial>
    <visual>
      <origin xyz="0 0 0" rpy="0 0 0" />
      <geometry>
        <mesh filename="package://gripx_description/meshes/meshes/shoulder_link.STL" />
      </geometry>
      <material name="">
        <color rgba="0.803 0.824 0.820 1" />
      </material>
    </visual>
    <collision>
      <origin xyz="0 0 0" rpy="0 0 0" />
      <geometry>
        <mesh filename="package://gripx_description/meshes/meshes/shoulder_link.STL" />
      </geometry>
    </collision>
  </link>

  <joint name="joint_1" type="revolute">
    <origin xyz="0 0 0.12825" rpy="0 0 0" />
    <parent link="base_link" />
    <child link="shoulder_link" />
    <axis xyz="0 0 1" />
    <limit lower="-2.69" upper="2.69" effort="10" velocity="1.6" />
  </joint>

  <link name="arm_link">
    <inertial>
      <origin xyz="0.02998299 0.21154808 0.0453031" rpy="0 0 0" />
      <mass value="1.17756164" />
      <inertia ixx="0.01149277" ixy="1E-06" ixz="1.6E-07" iyy="0.00102851" iyz="0.00140765" izz="0.01133492" />
    </inertial>
    <visual>
      <origin xyz="0 0 0" rpy="0 0 0" />
      <geometry>
        <mesh filename="package://gripx_description/meshes/meshes/arm_link.STL" />
      </geometry>
      <material name="">
        <color rgba="0.803 0.824 0.820 1" />
      </material>
    </visual>
    <collision>
      <origin xyz="0 0 0" rpy="0 0 0" />
      <geometry>
        <mesh filename="package://gripx_description/meshes/meshes/arm_link.STL" />
      </geometry>
    </collision>
  </link>

  <joint name="joint_2" type="revolute">
    <origin xyz="0 -0.03 0.115" rpy="1.5708 0 0" />
    <parent link="shoulder_link" />
    <child link="arm_link" />
    <axis xyz="0 0 1" />
    <limit lower="-2.69" upper="2.69" effort="14" velocity="1.6" />
  </joint>


  <link name="forearm_link">
    <inertial>
      <origin xyz="0.0301559 0.09502206 0.0073555" rpy="0 0 0" />
      <mass value="0.59767669" />
      <inertia ixx="0.00163256" ixy="7.11E-06" ixz="1.54E-06" iyy="0.00029798" iyz="9.587E-05" izz="0.00169091" />
    </inertial>
    <visual>
      <origin xyz="0 0 0" rpy="0 0 0" />
      <geometry>
        <mesh filename="package://gripx_description/meshes/meshes/forearm_link.STL" />
      </geometry>
      <material name="">
        <color rgba="0.803 0.824 0.820 1" />
      </material>
    </visual>
    <collision>
      <origin xyz="0 0 0" rpy="0 0 0" />
      <geometry>
        <mesh filename="package://gripx_description/meshes/meshes/forearm_link.STL" />
      </geometry>
    </collision>
  </link>
  <!-- <gazebo reference="forearm_link">
    <material>Kortex/Gray</material>
  <gazebo> -->
  <joint name="joint_3" type="revolute">
    <origin xyz="0 0.28 0" rpy="-3.1416 0 0" />
    <parent link="arm_link" />
    <child link="forearm_link" />
    <axis xyz="0 0 1" />
    <limit lower="-2.69" upper="2.69" effort="10" velocity="1.6" />
  </joint>
  <link name="lower_wrist_link">
    <inertial>
      <origin xyz="0.00575149 0.01000443 0.08719207" rpy="0 0 0" />
      <mass value="0.52693412" />
      <inertia ixx="0.00069098" ixy="2.4E-07" ixz="0.00016483" iyy="0.00078519" iyz="7.4E-07" izz="0.00034115" />
    </inertial>
    <visual>
      <origin xyz="0 0 0" rpy="0 0 0" />
      <geometry>
        <mesh filename="package://gripx_description/meshes/meshes/lower_wrist_link.STL" />
      </geometry>
      <material name="">
        <color rgba="0.803 0.824 0.820 1" />
      </material>
    </visual>
    <collision>
      <origin xyz="0 0 0" rpy="0 0 0" />
      <geometry>
        <mesh filename="package://gripx_description/meshes/meshes/lower_wrist_link.STL" />
      </geometry>
    </collision>
  </link>
  <!-- <gazebo reference="lower_wrist_link">
    <material>Kortex/Gray</material>
  <gazebo> -->
  <joint name="joint_4" type="revolute">
    <origin xyz="0 -0.14 0.02" rpy="1.5708 0 0" />
    <parent link="forearm_link" />
    <child link="lower_wrist_link" />
    <axis xyz="0 0 1" />
    <limit lower="-2.59" upper="2.59" effort="7" velocity="1.6" />
  </joint>
  <link name="upper_wrist_link">
    <inertial>
      <origin xyz="0.08056517 0.00980409 0.01872799" rpy="0 0 0" />
      <mass value="0.58097325" />
      <inertia ixx="0.00021268" ixy="5.21E-06" ixz="2.91E-06" iyy="0.00106371" iyz="1.1E-07" izz="0.00108465" />
    </inertial>
    <visual>
      <origin xyz="0 0 0" rpy="0 0 0" />
      <geometry>
        <mesh filename="package://gripx_description/meshes/meshes/upper_wrist_link.STL" />
      </geometry>
      <material name="">
        <color rgba="0.803 0.824 0.820 1" />
      </material>
    </visual>
    <collision>
      <origin xyz="0 0 0" rpy="0 0 0" />
      <geometry>
        <mesh filename="package://gripx_description/meshes/meshes/upper_wrist_link.STL" />
      </geometry>
    </collision>
  </link>
  <!-- <gazebo reference="upper_wrist_link">
    <material>Kortex/Gray</material>
  <gazebo> -->
  <joint name="joint_5" type="revolute">
    <origin xyz="0.0285 0 0.105" rpy="0 1.5708 0" />
    <parent link="lower_wrist_link" />
    <child link="upper_wrist_link" />
    <axis xyz="0 0 1" />
    <limit lower="-2.57" upper="2.57" effort="7" velocity="1.6" />
  </joint>

 <!--  <link name="end_effector_link"/> -->
  <!-- <joint name="joint_6" type="revolute">
    <origin xyz="-0.105 0 0.0285" rpy="0 -1.5708 0" />
    <parent link="upper_wrist_link" />
    <child link="gripx" />
    <axis xyz="0 0 1" />
    <limit lower="-2.59" upper="2.59" effort="7" velocity="3.2" />
  </joint> -->


  <link name="gripx">
      <inertial>
        <!-- <origin xyz="0.08056517 0.00980409 0.01872799" rpy="0 0 0" /> -->
        <origin xyz="0.18056517 0.00980409 0.272799" rpy="0 0 0" />
        <mass value="0.58097325" />
        <inertia ixx="0.00021268" ixy="5.21E-06" ixz="2.91E-06" iyy="0.00106371" iyz="1.1E-07" izz="0.00108465" />
      </inertial>
      <visual>
        <origin xyz="0.035 0 0" rpy="-1.5708 1.5708 0" />
        <geometry>
            <mesh filename="package://gripx_description/meshes/GripX.stl" scale="0.001 0.001 0.001"/>
          </geometry>
        <material name="">
          <color rgba="0.803 0.824 0.820 1" />
        </material>
      </visual>
      <collision>
        <origin xyz="0 0 0" rpy="0 0 0" />
        <geometry>
          <mesh filename="package://gripx_description/meshes/GripX.stl" scale="0.001 0.001 0.001"/>
        </geometry>
      </collision>
    </link>

  <joint name="joint_6" type="revolute">
    <origin xyz="-0.485 0.0 0.03" rpy="0 0 0" />
    <parent link="upper_wrist_link" />
    <child link="gripx" />
    <limit lower="-2.57" upper="2.57" effort="7" velocity="1.6" />
  </joint>

<!--

  <link name="end_effector_link"/>
  <joint name="joint_6" type="revolute">
    <origin xyz="-0.105 0 0.0285" rpy="0 -1.5708 0" />
    <parent link="upper_wrist_link" />
    <child link="end_effector_link" />
    <axis xyz="0 0 1" />
    <limit lower="-2.59" upper="2.59" effort="7" velocity="3.2" />
  </joint>
  <link name="GripX" />
  <joint name="end_effector" type="fixed">
    <origin xyz="0 0 0" rpy="0 0 0" />
    <geometry>
        <mesh filename="package://urdf_tutorial/meshes/GripX.stl" scale="0.001 0.001 0.001"/>
      </geometry>
    <parent link="end_effector_link" />
    <child link="GripX" />
    <axis xyz="0 0 1" />
    <limit lower="0" upper="0" effort="0" velocity="0" />
  </joint>
--> 

<!-- Adding GripX 
  <link name="GripX"/>
  <joint name="joint_6" type="revolute">
    <origin xyz="-0.105 0 0.0285" rpy="0 -1.5708 0" />
    <parent link="upper_wrist_link" />
    <child link="end_effector_link" />
    <axis xyz="0 0 1" />
    <limit lower="-2.59" upper="2.59" effort="7" velocity="3.2" />
  </joint>
  <link name="dummy_link" />
  <joint name="end_effector" type="fixed">
    <origin xyz="0 0 0" rpy="0 0 0" />
    <parent link="end_effector_link" />
    <child link="dummy_link" />
    <axis xyz="0 0 1" />
    <limit lower="0" upper="0" effort="0" velocity="0" />
  </joint>
-->

</robot>
