<?xml version="1.0"?>
<robot name="gripx" xmlns:xacro="http://ros.org/wiki/xacro">

  <material name="blue">
    <color rgba="0 0 0.8 1"/>
  </material>
  <material name="black">
    <color rgba="0 0 0 1"/>
  </material>
  <material name="white">
    <color rgba="1 1 1 1"/>
  </material>

  <!--     Used for fixing robot to Gazebo 'base_link'   -->
  <link name="world"/>

  <joint name="fixed" type="fixed">
    <parent link="world"/>
    <child link="base_link"/>
  </joint>


  <link name="base_link">
    <inertial>
      <origin xyz="0.00244324 0.00015573 0.08616742" rpy="0 0 0" />
      <mass value="1.14608471" />
      <inertia ixx="0.00335854" ixy="3.9E-07" ixz="0.00010989" iyy="0.003311" iyz="1.91E-06" izz="0.00077158" />
    </inertial>
    <visual>
      <origin xyz="0 0 0" rpy="0 0 0" />
      <geometry>
        <mesh filename="package://gripx_description/meshes/meshes/base_link.STL" />
      </geometry>
      <material name="">
        <color rgba="0.803 0.824 0.820 1" />
      </material>
    </visual>
    <collision>
      <origin xyz="0 0 0" rpy="0 0 0" />
      <geometry>
        <mesh filename="package://gripx_description/meshes/meshes/base_link.STL" />
      </geometry>
    </collision>
  </link>


  <link name="shoulder_link">
    <inertial>
      <origin xyz="2.477E-05 0.02213531 0.09937686" rpy="0 0 0" />
      <mass value="0.95974404" />
      <inertia ixx="0.00165947" ixy="2E-08" ixz="3.6E-07" iyy="0.00140355" iyz="0.00034927" izz="0.00089493" />
    </inertial>
    <visual>
      <origin xyz="0 0 0" rpy="0 0 0" />
      <geometry>
        <mesh filename="package://gripx_description/meshes/meshes/shoulder_link.STL" />
      </geometry>
      <material name="">
        <color rgba="0.803 0.824 0.820 1" />
      </material>
    </visual>
    <collision>
      <origin xyz="0 0 0" rpy="0 0 0" />
      <geometry>
        <mesh filename="package://gripx_description/meshes/meshes/shoulder_link.STL" />
      </geometry>
    </collision>
  </link>

  <joint name="joint_1" type="revolute">
    <origin xyz="0 0 0.12825" rpy="0 0 0" />
    <parent link="base_link" />
    <child link="shoulder_link" />
    <axis xyz="0 0 1" />
    <limit lower="-2.69" upper="2.69" effort="10" velocity="1.6" />
  </joint>

  <!-- Create the first transmission -->
  <transmission name="joint_1__trans" type="SimpleTransmission">
    <type>transmission_interface/SimpleTransmission</type>
    <actuator name="joint_1_extension_motor">
      <mechanicalReduction>1</mechanicalReduction>
    </actuator>
    <joint name="joint_1">
      <hardwareInterface>hardware_interface/PositionJointInterface</hardwareInterface>
    </joint>
  </transmission>



  <link name="arm_link">
    <inertial>
      <origin xyz="0.02998299 0.21154808 0.0453031" rpy="0 0 0" />
      <mass value="1.17756164" />
      <inertia ixx="0.01149277" ixy="1E-06" ixz="1.6E-07" iyy="0.00102851" iyz="0.00140765" izz="0.01133492" />
    </inertial>
    <visual>
      <origin xyz="0 0 0" rpy="0 0 0" />
      <geometry>
        <mesh filename="package://gripx_description/meshes/meshes/arm_link.STL" />
      </geometry>
      <material name="">
        <color rgba="0.803 0.824 0.820 1" />
      </material>
    </visual>
    <collision>
      <origin xyz="0 0 0" rpy="0 0 0" />
      <geometry>
        <mesh filename="package://gripx_description/meshes/meshes/arm_link.STL" />
      </geometry>
    </collision>
  </link>

  <joint name="joint_2" type="revolute">
    <origin xyz="0 -0.03 0.115" rpy="1.5708 0 0" />
    <parent link="shoulder_link" />
    <child link="arm_link" />
    <axis xyz="0 0 1" />
    <limit lower="-2.69" upper="2.69" effort="14" velocity="1.6" />
  </joint>

  <!-- Create the second transmission -->
  <transmission name="joint_2__trans" type="SimpleTransmission">
    <type>transmission_interface/SimpleTransmission</type>
    <actuator name="joint_2_extension_motor">
      <mechanicalReduction>1</mechanicalReduction>
    </actuator>
    <joint name="joint_2">
      <hardwareInterface>hardware_interface/PositionJointInterface</hardwareInterface>
    </joint>
  </transmission>


  <link name="forearm_link">
    <inertial>
      <origin xyz="0.0301559 0.09502206 0.0073555" rpy="0 0 0" />
      <mass value="0.59767669" />
      <inertia ixx="0.00163256" ixy="7.11E-06" ixz="1.54E-06" iyy="0.00029798" iyz="9.587E-05" izz="0.00169091" />
    </inertial>
    <visual>
      <origin xyz="0 0 0" rpy="0 0 0" />
      <geometry>
        <mesh filename="package://gripx_description/meshes/meshes/forearm_link.STL" />
      </geometry>
      <material name="">
        <color rgba="0.803 0.824 0.820 1" />
      </material>
    </visual>
    <collision>
      <origin xyz="0 0 0" rpy="0 0 0" />
      <geometry>
        <mesh filename="package://gripx_description/meshes/meshes/forearm_link.STL" />
      </geometry>
    </collision>
  </link>
  <!-- <gazebo reference="forearm_link">
    <material>Kortex/Gray</material>
    <gazebo> -->
      <joint name="joint_3" type="revolute">
        <origin xyz="0 0.28 0" rpy="-3.1416 0 0" />
        <parent link="arm_link" />
        <child link="forearm_link" />
        <axis xyz="0 0 1" />
        <limit lower="-2.69" upper="2.69" effort="10" velocity="1.6" />
      </joint>
      <link name="lower_wrist_link">
        <inertial>
          <origin xyz="0.00575149 0.01000443 0.08719207" rpy="0 0 0" />
          <mass value="0.52693412" />
          <inertia ixx="0.00069098" ixy="2.4E-07" ixz="0.00016483" iyy="0.00078519" iyz="7.4E-07" izz="0.00034115" />
        </inertial>
        <visual>
          <origin xyz="0 0 0" rpy="0 0 0" />
          <geometry>
            <mesh filename="package://gripx_description/meshes/meshes/lower_wrist_link.STL" />
          </geometry>
          <material name="">
            <color rgba="0.803 0.824 0.820 1" />
          </material>
        </visual>
        <collision>
          <origin xyz="0 0 0" rpy="0 0 0" />
          <geometry>
            <mesh filename="package://gripx_description/meshes/meshes/lower_wrist_link.STL" />
          </geometry>
        </collision>
      </link>

      <!-- Create the first transmission -->
      <transmission name="joint_3__trans" type="SimpleTransmission">
        <type>transmission_interface/SimpleTransmission</type>
        <actuator name="joint_3_extension_motor">
          <mechanicalReduction>1</mechanicalReduction>
        </actuator>
        <joint name="joint_3">
          <hardwareInterface>hardware_interface/PositionJointInterface</hardwareInterface>
        </joint>
      </transmission>

  <!-- <gazebo reference="lower_wrist_link">
    <material>Kortex/Gray</material>
    <gazebo> -->
      <joint name="joint_4" type="revolute">
        <origin xyz="0 -0.14 0.02" rpy="1.5708 0 0" />
        <parent link="forearm_link" />
        <child link="lower_wrist_link" />
        <axis xyz="0 0 1" />
        <limit lower="-2.59" upper="2.59" effort="7" velocity="1.6" />
      </joint>
      <link name="upper_wrist_link">
        <inertial>
          <origin xyz="0.08056517 0.00980409 0.01872799" rpy="0 0 0" />
          <mass value="0.58097325" />
          <inertia ixx="0.00021268" ixy="5.21E-06" ixz="2.91E-06" iyy="0.00106371" iyz="1.1E-07" izz="0.00108465" />
        </inertial>
        <visual>
          <origin xyz="0 0 0" rpy="0 0 0" />
          <geometry>
            <mesh filename="package://gripx_description/meshes/meshes/upper_wrist_link.STL" />
          </geometry>
          <material name="">
            <color rgba="0.803 0.824 0.820 1" />
          </material>
        </visual>
        <collision>
          <origin xyz="0 0 0" rpy="0 0 0" />
          <geometry>
            <mesh filename="package://gripx_description/meshes/meshes/upper_wrist_link.STL" />
          </geometry>
        </collision>
      </link>

      <!-- Create the first transmission -->
      <transmission name="joint_4__trans" type="SimpleTransmission">
        <type>transmission_interface/SimpleTransmission</type>
        <actuator name="joint_4_extension_motor">
          <mechanicalReduction>1</mechanicalReduction>
        </actuator>
        <joint name="joint_4">
          <hardwareInterface>hardware_interface/PositionJointInterface</hardwareInterface>
        </joint>
      </transmission>

  <!-- <gazebo reference="upper_wrist_link">
    <material>Kortex/Gray</material>
    <gazebo> -->
      <joint name="joint_5" type="revolute">
        <origin xyz="0.0285 0 0.105" rpy="0 1.5708 0" />
        <parent link="lower_wrist_link" />
        <child link="upper_wrist_link" />
        <axis xyz="0 0 1" />
        <limit lower="-2.57" upper="2.57" effort="7" velocity="1.6" />
      </joint>

      <!-- Create the first transmission -->
      <transmission name="joint_5__trans" type="SimpleTransmission">
        <type>transmission_interface/SimpleTransmission</type>
        <actuator name="joint_5_extension_motor">
          <mechanicalReduction>1</mechanicalReduction>
        </actuator>
        <joint name="joint_5">
          <hardwareInterface>hardware_interface/PositionJointInterface</hardwareInterface>
        </joint>
      </transmission>

      <link name="GripX">
        <inertial>
          <origin xyz="0.08056517 0.00980409 0.01872799" rpy="0 0 0" />
          <mass value="0.58097325" />
          <inertia ixx="0.00021268" ixy="5.21E-06" ixz="2.91E-06" iyy="0.00106371" iyz="1.1E-07" izz="0.00108465" />
        </inertial>
        <visual>
          <origin xyz="0.035 0 0" rpy="-1.5708 1.5708 0" />
          <geometry>
            <mesh filename="package://gripx_description/meshes/GripX.stl" scale="0.001 0.001 0.001"/>
          </geometry>
          <material name="">
            <color rgba="0.803 0.824 0.820 1" />
          </material>
        </visual>
        <collision>
          <origin xyz="0 0 0" rpy="0 0 0" />
          <geometry>
            <mesh filename="package://gripx_description/meshes/GripX.stl" scale="0.001 0.001 0.001"/>
          </geometry>
        </collision>
      </link>

      <joint name="joint_6" type="revolute">
        <origin xyz="-0.485 0.0 0.03" rpy="0 0 0" />
        <parent link="upper_wrist_link" />
        <child link="GripX" />
        <limit lower="-3.57" upper="3.57" effort="7" velocity="1.6" />
      </joint>

        <transmission name="joint_6__trans" type="SimpleTransmission">
        <type>transmission_interface/SimpleTransmission</type>
        <actuator name="joint_6_extension_motor">
          <mechanicalReduction>1</mechanicalReduction>
        </actuator>
        <joint name="joint_6">
          <hardwareInterface>hardware_interface/PositionJointInterface</hardwareInterface>
        </joint>
      </transmission>

<!--

  <link name="end_effector_link"/>
  <joint name="joint_6" type="revolute">
    <origin xyz="-0.105 0 0.0285" rpy="0 -1.5708 0" />
    <parent link="upper_wrist_link" />
    <child link="end_effector_link" />
    <axis xyz="0 0 1" />
    <limit lower="-2.59" upper="2.59" effort="7" velocity="3.2" />
  </joint>
  <link name="GripX" />
  <joint name="end_effector" type="fixed">
    <origin xyz="0 0 0" rpy="0 0 0" />
    <geometry>
        <mesh filename="package://gripx_description/meshes/GripX.stl" scale="0.001 0.001 0.001"/>
      </geometry>
    <parent link="end_effector_link" />
    <child link="GripX" />
    <axis xyz="0 0 1" />
    <limit lower="0" upper="0" effort="0" velocity="0" />
  </joint>
--> 

<!-- Adding GripX 
  <link name="GripX"/>
  <joint name="joint_6" type="revolute">
    <origin xyz="-0.105 0 0.0285" rpy="0 -1.5708 0" />
    <parent link="upper_wrist_link" />
    <child link="end_effector_link" />
    <axis xyz="0 0 1" />
    <limit lower="-2.59" upper="2.59" effort="7" velocity="3.2" />
  </joint>
  <link name="dummy_link" />
  <joint name="end_effector" type="fixed">
    <origin xyz="0 0 0" rpy="0 0 0" />
    <parent link="end_effector_link" />
    <child link="dummy_link" />
    <axis xyz="0 0 1" />
    <limit lower="0" upper="0" effort="0" velocity="0" />
  </joint>
-->
<!-- Gazebo plugin for ROS Control -->
<gazebo>
  <plugin name="gazebo_ros_control" filename="libgazebo_ros_control.so">
    <robotNamespace>/</robotNamespace>
  </plugin>



<!--   <plugin name="joint_state_publisher" filename="libgazebo_ros_joint_state_publisher.so">
    <robotNamespace>/</robotNamespace>
    <jointName>joint1, 
                joint_2, 
                   joint_3, 
                   joint_4, 
                   joint_5,
                   joint_6
        </jointName>
  </plugin> -->


</gazebo>
</robot>
